<?xml version="1.0" ?>
<!-- =================================================================================== -->
<!-- |    This document was autogenerated by xacro from powerball.urdf.xacro           | -->
<!-- |    EDITING THIS FILE BY HAND IS NOT RECOMMENDED                                 | -->
<!-- =================================================================================== -->
<robot name="powerball" xmlns:controller="http://playerstage.sourceforge.net/gazebo/xmlschema/#controller" xmlns:interface="http://playerstage.sourceforge.net/gazebo/xmlschema/#interface" xmlns:sensor="http://playerstage.sourceforge.net/gazebo/xmlschema/#sensor" xmlns:xacro="http://ros.org/wiki/xacro">
  <!-- common stuff -->
  <material name="Blue">
    <color rgba="0.0 0.0 0.8 1.0"/>
  </material>
  <material name="Green">
    <color rgba="0.0 0.8 0.0 1.0"/>
  </material>
  <material name="Grey">
    <color rgba="0.7 0.7 0.7 1.0"/>
  </material>
  <material name="Grey2">
    <color rgba="0.9 0.9 0.9 1.0"/>
  </material>
  <material name="Red">
    <color rgba="0.8 0.0 0.0 1.0"/>
  </material>
  <material name="White">
    <color rgba="1.0 1.0 1.0 1.0"/>
  </material>
  <material name="Black">
    <color rgba="0.0 0.0 0.0 1.0"/>
  </material>
  <material name="Caster">
    <texture filename="package://pr2_ogre/Media/materials/textures/pr2_caster_texture.png"/>
  </material>
  <material name="Wheel_l">
    <texture filename="package://pr2_ogre/Media/materials/textures/pr2_wheel_left.png"/>
  </material>
  <material name="Wheel_r">
    <texture filename="package://pr2_ogre/Media/materials/textures/pr2_wheel_right.png"/>
  </material>
  <material name="RollLinks">
    <texture filename="package://pr2_ogre/Media/materials/textures/pr2_wheel_left.png"/>
  </material>
  <gazebo>
    <controller:gazebo_ros_controller_manager name="gazebo_ros_controller_manager" plugin="libgazebo_ros_controller_manager.so">
      <alwaysOn>true</alwaysOn>
      <updateRate>1000.0</updateRate>
      <interface:audio name="gazebo_ros_controller_manager_dummy_iface"/>
    </controller:gazebo_ros_controller_manager>
    <controller:gazebo_ros_power_monitor name="gazebo_ros_power_monitor_controller" plugin="libgazebo_ros_power_monitor.so">
      <alwaysOn>true</alwaysOn>
      <updateRate>1.0</updateRate>
      <timeout>5</timeout>
      <interface:audio name="power_monitor_dummy_interface"/>
      <powerStateTopic>power_state</powerStateTopic>
      <powerStateRate>10.0</powerStateRate>
      <fullChargeCapacity>87.78</fullChargeCapacity>
      <dischargeRate>-474</dischargeRate>
      <chargeRate>525</chargeRate>
      <dischargeVoltage>15.52</dischargeVoltage>
      <chargeVoltage>16.41</chargeVoltage>
    </controller:gazebo_ros_power_monitor>
  </gazebo>
  <!-- calibration -->
  <!-- schunk powerball -->
  <!-- foot for arm -->
  <link name="base_link">
    <inertial>
      <origin rpy="0 0 0" xyz="0 0 -10"/>
      <mass value="1000.0"/>
      <inertia ixx="100.0" ixy="0" ixz="0" iyy="100.0" iyz="0" izz="100.0"/>
    </inertial>
    <visual>
      <origin rpy="0 0 0" xyz="0 0 0.07"/>
      <geometry>
        <cylinder length="0.14" radius="0.1"/>
      </geometry>
      <material name="Grey"/>
    </visual>
    <collision>
      <origin rpy="0 0 0" xyz="0 0 0.25"/>
      <geometry>
        <cylinder length="0.5" radius="0.1"/>
      </geometry>
    </collision>
  </link>
  <!-- arm -->
  <joint name="arm_0_joint" type="fixed">
    <origin rpy="0 0 0" xyz="0 0 0.14"/>
    <parent link="base_link"/>
    <child link="arm_0_link"/>
  </joint>
  <link name="arm_0_link">
    <inertial>
      <origin rpy="0 0 0" xyz="0 0 0"/>
      <mass value="0.29364"/>
      <inertia ixx="0.01" ixy="0" ixz="0" iyy="0.01" iyz="0" izz="0.01"/>
    </inertial>
    <visual>
      <origin rpy="0 0 0" xyz="0 0 0"/>
      <geometry>
        <mesh filename="package://robotnik_powerball_description/meshes/powerball0.stl"/>
      </geometry>
      <material name="Grey"/>
    </visual>
    <collision>
      <origin rpy="0 0 0" xyz="0 0 0"/>
      <geometry>
        <mesh filename="package://robotnik_powerball_description/meshes/powerball0.stl"/>
      </geometry>
    </collision>
  </link>
  <joint name="arm_1_joint" type="revolute">
    <origin rpy="0 0 0" xyz="0 0 0.0897"/>
    <parent link="arm_0_link"/>
    <child link="arm_1_link"/>
    <axis xyz="0 0 -1"/>
    <!--axis xyz="0 0 1"/-->
    <calibration rising="0"/>
    <dynamics damping="10"/>
    <limit effort="370" lower="-2.97" upper="2.97" velocity="2.0"/>
    <safety_controller k_position="20" k_velocity="50" soft_lower_limit="-6.2731853" soft_upper_limit="6.2731853"/>
  </joint>
  <link name="arm_1_link">
    <inertial>
      <origin rpy="0 0 0" xyz="0 0 0"/>
      <mass value="0.29364"/>
      <inertia ixx="0.01" ixy="0" ixz="0" iyy="0.01" iyz="0" izz="0.01"/>
    </inertial>
    <visual>
      <origin rpy="0 0 0" xyz="0 0 0"/>
      <geometry>
        <mesh filename="package://robotnik_powerball_description/meshes/powerball1.stl"/>
      </geometry>
      <material name="Blue"/>
    </visual>
    <collision>
      <origin rpy="0 0 0" xyz="0 0 0"/>
      <geometry>
        <mesh filename="package://robotnik_powerball_description/meshes/powerball1.stl"/>
      </geometry>
    </collision>
  </link>
  <joint name="arm_2_joint" type="revolute">
    <origin rpy="-1.5708 0 3.14159" xyz="0 0 0"/>
    <parent link="arm_1_link"/>
    <child link="arm_2_link"/>
    <axis xyz="0 0 -1"/>
    <calibration rising="0"/>
    <dynamics damping="10"/>
    <limit effort="370" lower="-1.92" upper="1.92" velocity="2.0"/>
    <safety_controller k_position="20" k_velocity="50" soft_lower_limit="-2.0843" soft_upper_limit="2.0843"/>
  </joint>
  <link name="arm_2_link">
    <inertial>
      <origin rpy="0 0 0" xyz="0 0 0"/>
      <mass value="1.68311"/>
      <inertia ixx="0.03" ixy="0" ixz="0" iyy="0.03" iyz="0" izz="0.03"/>
    </inertial>
    <visual>
      <origin rpy="0 0 0" xyz="0 0 0"/>
      <geometry>
        <mesh filename="package://robotnik_powerball_description/meshes/powerball2.stl"/>
      </geometry>
      <material name="Grey"/>
    </visual>
    <collision>
      <origin rpy="0 0 0" xyz="0 0 0"/>
      <geometry>
        <mesh filename="package://robotnik_powerball_description/meshes/powerball2.stl"/>
      </geometry>
    </collision>
  </link>
  <joint name="arm_3_joint" type="revolute">
    <origin rpy="3.14159 0 0" xyz="0 -0.350 0"/>
    <parent link="arm_2_link"/>
    <child link="arm_3_link"/>
    <axis xyz="0 0 -1"/>
    <calibration rising="0"/>
    <dynamics damping="5"/>
    <limit effort="176" lower="-2.71" upper="2.71" velocity="2.0"/>
    <safety_controller k_position="20" k_velocity="25" soft_lower_limit="-6.2731853" soft_upper_limit="6.2731853"/>
  </joint>
  <link name="arm_3_link">
    <inertial>
      <origin rpy="0 0 0" xyz="0 0 0"/>
      <mass value="2.1"/>
      <inertia ixx="0.03" ixy="0" ixz="0" iyy="0.03" iyz="0" izz="0.03"/>
    </inertial>
    <visual>
      <origin rpy="0 0 0" xyz="0 0 0"/>
      <geometry>
        <mesh filename="package://robotnik_powerball_description/meshes/powerball3.stl"/>
      </geometry>
      <material name="Blue"/>
    </visual>
    <collision>
      <origin rpy="0 0 0" xyz="0 0 0"/>
      <geometry>
        <mesh filename="package://robotnik_powerball_description/meshes/powerball3.stl"/>
      </geometry>
    </collision>
  </link>
  <joint name="arm_4_joint" type="revolute">
    <origin rpy="1.5708 3.14159 0" xyz="0 0 0"/>
    <parent link="arm_3_link"/>
    <child link="arm_4_link"/>
    <axis xyz="0 0 1"/>
    <calibration rising="0"/>
    <dynamics damping="5"/>
    <limit effort="176" lower="-2.97" upper="2.97" velocity="2.0"/>
    <safety_controller k_position="20" k_velocity="25" soft_lower_limit="-2.0843951" soft_upper_limit="2.0843951"/>
  </joint>
  <link name="arm_4_link">
    <inertial>
      <origin rpy="0 0 0" xyz="0 0 0"/>
      <mass value="1.68311"/>
      <inertia ixx="0.03" ixy="0" ixz="0" iyy="0.03" iyz="0" izz="0.03"/>
    </inertial>
    <visual>
      <origin rpy="0 0 0" xyz="0 0 0"/>
      <geometry>
        <mesh filename="package://robotnik_powerball_description/meshes/powerball4.stl"/>
      </geometry>
      <material name="Grey"/>
    </visual>
    <collision>
      <origin rpy="0 0 0" xyz="0 0 0"/>
      <geometry>
        <mesh filename="package://robotnik_powerball_description/meshes/powerball4.stl"/>
      </geometry>
    </collision>
  </link>
  <joint name="arm_5_joint" type="revolute">
    <origin rpy="1.5708 0 0" xyz="0 0.005 -0.3049"/>
    <parent link="arm_4_link"/>
    <child link="arm_5_link"/>
    <axis xyz="0 0 -1"/>
    <calibration rising="0"/>
    <dynamics damping="5"/>
    <limit effort="41.6" lower="-2.44" upper="2.44" velocity="2.0"/>
    <safety_controller k_position="20" k_velocity="25" soft_lower_limit="-6.2731853" soft_upper_limit="6.2731853"/>
  </joint>
  <link name="arm_5_link">
    <inertial>
      <origin rpy="0 0 0" xyz="0 0 0"/>
      <mass value="0.807"/>
      <inertia ixx="0.03" ixy="0" ixz="0" iyy="0.03" iyz="0" izz="0.03"/>
    </inertial>
    <visual>
      <origin rpy="0 0 0" xyz="0 0 0"/>
      <geometry>
        <mesh filename="package://robotnik_powerball_description/meshes/powerball5.stl"/>
      </geometry>
      <material name="Blue"/>
    </visual>
    <collision>
      <origin rpy="0 0 0" xyz="0 0 0"/>
      <geometry>
        <mesh filename="package://robotnik_powerball_description/meshes/powerball5.stl"/>
      </geometry>
    </collision>
  </link>
  <joint name="arm_6_joint" type="revolute">
    <origin rpy="-1.5708 0 0" xyz="0 0 0"/>
    <parent link="arm_5_link"/>
    <child link="arm_6_link"/>
    <axis xyz="0 0 -1"/>
    <calibration rising="0"/>
    <dynamics damping="5"/>
    <limit effort="20.1" lower="-2.97" upper="2.97" velocity="2.0"/>
    <safety_controller k_position="20" k_velocity="25" soft_lower_limit="-2.0843951" soft_upper_limit="2.0843951"/>
  </joint>
  <link name="arm_6_link">
    <inertial>
      <origin rpy="0 0 0" xyz="0 0 0"/>
      <mass value="0.819"/>
      <inertia ixx="0.01" ixy="0" ixz="0" iyy="0.01" iyz="0" izz="0.01"/>
    </inertial>
    <visual>
      <origin rpy="0 0 0" xyz="0 0 0"/>
      <geometry>
        <mesh filename="package://robotnik_powerball_description/meshes/powerball6.stl"/>
      </geometry>
      <material name="Grey"/>
    </visual>
    <collision>
      <origin rpy="0 0 0" xyz="0 0 0"/>
      <geometry>
        <mesh filename="package://robotnik_powerball_description/meshes/powerball6.stl"/>
      </geometry>
    </collision>
  </link>
  <gazebo reference="arm_0_link">
    <material value="PR2/Grey"/>
    <turnGravityOff>false</turnGravityOff>
    <selfCollide>true</selfCollide>
  </gazebo>
  <gazebo reference="arm_1_link">
    <material value="PR2/Blue"/>
    <turnGravityOff>false</turnGravityOff>
    <selfCollide>true</selfCollide>
  </gazebo>
  <gazebo reference="arm_2_link">
    <material value="PR2/Grey"/>
    <turnGravityOff>false</turnGravityOff>
    <selfCollide>true</selfCollide>
  </gazebo>
  <gazebo reference="arm_3_link">
    <material value="PR2/Blue"/>
    <turnGravityOff>false</turnGravityOff>
    <selfCollide>true</selfCollide>
  </gazebo>
  <gazebo reference="arm_4_link">
    <material value="PR2/Grey"/>
    <turnGravityOff>false</turnGravityOff>
    <selfCollide>true</selfCollide>
  </gazebo>
  <gazebo reference="arm_5_link">
    <material value="PR2/Blue"/>
    <turnGravityOff>false</turnGravityOff>
    <selfCollide>true</selfCollide>
  </gazebo>
  <gazebo reference="arm_6_link">
    <material value="PR2/Grey"/>
    <turnGravityOff>false</turnGravityOff>
    <selfCollide>true</selfCollide>
  </gazebo>
  <transmission name="arm_1_trans" type="pr2_mechanism_model/SimpleTransmission">
    <actuator name="arm_1_motor"/>
    <joint name="arm_1_joint"/>
    <mechanicalReduction>1</mechanicalReduction>
  </transmission>
  <transmission name="arm_2_trans" type="pr2_mechanism_model/SimpleTransmission">
    <actuator name="arm_2_motor"/>
    <joint name="arm_2_joint"/>
    <mechanicalReduction>1</mechanicalReduction>
  </transmission>
  <transmission name="arm_3_trans" type="pr2_mechanism_model/SimpleTransmission">
    <actuator name="arm_3_motor"/>
    <joint name="arm_3_joint"/>
    <mechanicalReduction>1</mechanicalReduction>
  </transmission>
  <transmission name="arm_4_trans" type="pr2_mechanism_model/SimpleTransmission">
    <actuator name="arm_4_motor"/>
    <joint name="arm_4_joint"/>
    <mechanicalReduction>1</mechanicalReduction>
  </transmission>
  <transmission name="arm_5_trans" type="pr2_mechanism_model/SimpleTransmission">
    <actuator name="arm_5_motor"/>
    <joint name="arm_5_joint"/>
    <mechanicalReduction>1</mechanicalReduction>
  </transmission>
  <transmission name="arm_6_trans" type="pr2_mechanism_model/SimpleTransmission">
    <actuator name="arm_6_motor"/>
    <joint name="arm_6_joint"/>
    <mechanicalReduction>1</mechanicalReduction>
  </transmission>

  
  <!-- GRIPPER -->
  
  <joint name="arm_gripper_joint" type="fixed">
    <origin rpy="3.1415 0 0" xyz="0 0 -0.085"/>
    <parent link="arm_6_link"/>
    <child link="gripper_base_link"/>
  </joint>
  
 <!-- BASE LINK -->
 <link name="gripper_base_link">
      <inertial>
          <mass value="1.2" />
          <origin xyz="0 0 0" />
     	  <!--inertia ixx="1.0" ixy="0.0" ixz="0.0"
               iyy="100.0" iyz="0.0" 
               izz="1.0" /-->
      	  <inertia  ixx="1.0" ixy="0.0"  ixz="0.0"  iyy="1.0"  iyz="0.0"  izz="1.0" />
      </inertial>

      <visual>
          <origin xyz="0.0 0 0" rpy="0 0 0" />
          <geometry>
             <mesh filename="package://wsg_50_simulation/meshes/WSG50_110.stl" scale="1 1 1"/>
	     <!--box size="0.146 0.05 0.0735"/-->
          </geometry>
          <material name="grey">
		<color rgba="0.5 0.5 0.5 1"/>
      	  </material>
      </visual>

      <collision>
          <origin xyz="0.0 0 0" rpy="0 0 0" />
          <geometry>
	     <!--box size="0.146 0.05 0.0735"/-->
             <mesh filename="package://wsg_50_simulation/meshes/WSG50_110.stl" scale="1 1 1"/>
         </geometry>
     </collision>
  </link>

  <gazebo reference="gripper_base_link">
    <material>Gazebo/Grey</material>
    <turnGravityOff>false</turnGravityOff>
  </gazebo>
  
  
  <!-- TOOL LINK -->
  
  <joint name="gripper_base_link_tool_joint" type="fixed">
     <origin xyz="0 0 0.22" rpy="0 0 0" />  
     <parent link="gripper_base_link"/>
     <child link="tool_link" />
     <dynamics friction="100" damping="100" />
     <axis xyz="1 0 0"/>
     <limit effort="100" velocity="100"/>
  </joint>
  
   <link name="tool_link">
      <inertial>
          <mass value="0.001" />
          <origin xyz="0 0 0" />
      	  <inertia  ixx="1.0" ixy="0.0"  ixz="0.0"  iyy="1.0"  iyz="0.0"  izz="1.0" />
      </inertial>

      <visual>
          <origin xyz="0.0 0 0" rpy="0 0 0" />
          <geometry>
			<box size="0.000005 0.000005 0.000005"/>
          </geometry>
          <material name="red">
			<color rgba="1 0 0 1"/>
      	  </material>
      </visual>
  </link>


  <!-- GRIPPER LEFT -->

  <joint name="base_joint_gripper_left" type="prismatic">
     <limit lower="-0.055" upper="-0.0027" effort="1.0" velocity="1.0"/>
     <origin xyz="0 0 0" rpy="0 0 0" />      <!--origin xyz="-0.0067 0 0.049" rpy="0 0 0" /-->
     <parent link="gripper_base_link"/>
     <child link="gripper_left" />
     <dynamics friction="100" damping="100" />
     <axis xyz="1 0 0"/>
     <limit effort="100" velocity="100"/>
  </joint>

  <transmission name="base_trans_left" type="pr2_mechanism_model/SimpleTransmission">
     <actuator name="base_motor_left" />
     <joint name="base_joint_gripper_left" />
     <mechanicalReduction>1</mechanicalReduction>
     <motorTorqueConstant>1</motorTorqueConstant>
  </transmission>

  <link name="gripper_left">
      <inertial>
          <mass value="0.1" />
          <origin xyz="0 0 0" />
      <inertia ixx="1.0" ixy="0.0" ixz="0.0"
               iyy="1.0" iyz="0.0" 
               izz="1.0" />
      </inertial>

      <visual>
          <origin xyz="0.0 0 0" rpy="0 0 0" />
          <geometry>
             <mesh filename="package://wsg_50_simulation/meshes/GUIDE_WSG50_110.stl" scale="0.001 0.001 0.001"/>
	     <!--box size="0.0175 0.03 0.024"/-->
          </geometry>
          <material name="black">
		<color rgba="0 0 0 0"/>
      	  </material>
      </visual>

      <collision>
          <origin xyz="0 0 0" rpy="0 0 0" />
          <geometry>
	     <!--box size="0.0175 0.03 0.024"/-->
             <mesh filename="package://wsg_50_simulation/meshes/GUIDE_WSG50_110.stl" scale="0.001 0.001 0.001"/>
         </geometry>
     </collision>
  </link>

  <gazebo reference="gripper_left">
    <material>Gazebo/Blue</material>
    <turnGravityOff>false</turnGravityOff>
  </gazebo>


  <!-- LEFT FINGER -->

  <joint name="guide_joint_finger_left" type="fixed">
     <origin xyz="0 0 0.023" rpy="0 0 0" />
     <parent link="gripper_left"/>
     <child link="finger_left" />
     <dynamics friction="100" damping="100" />
     <axis xyz="1 0 0"/>
     <limit effort="100" velocity="100"/>
  </joint>

  <link name="finger_left">
      <inertial>
          <mass value="0.1" />
          <origin xyz="0 0 0" />
      <inertia ixx="1.0" ixy="0.0" ixz="0.0"
               iyy="1.0" iyz="0.0" 
               izz="1.0" />
      </inertial>

      <visual>
          <origin xyz="0.0 0 0" rpy="0 0 0" />
          <geometry>
             <mesh filename="package://wsg_50_simulation/meshes/WSG-FMF.stl" scale="0.001 0.001 0.001"/>
          </geometry>
          <material name="black">
		<color rgba="0 0 0 0"/>
      	  </material>
      </visual>

      <collision>
          <origin xyz="0 0 0" rpy="0 0 0" />
          <geometry>
             <mesh filename="package://wsg_50_simulation/meshes/WSG-FMF.stl" scale="0.001 0.001 0.001"/>
         </geometry>
     </collision>
  </link>

  <gazebo reference="finger_left">
    <material>Gazebo/Blue</material>
    <turnGravityOff>false</turnGravityOff>
  </gazebo>


  <!-- GRIPPER RIGHT -->

  <joint name="base_joint_gripper_right" type="prismatic">
     <limit lower="0.0027" upper="0.055" effort="1.0" velocity="1.0"/>
     <origin xyz="0 0 0" rpy="0 0 3.14159" />
     <parent link="gripper_base_link"/>
     <child link="gripper_right" />
     <axis xyz="-1 0 0"/>
     <dynamics friction="100" damping="100" />
     <limit effort="100" velocity="100"/>
  </joint>

  <transmission name="base_trans_right" type="pr2_mechanism_model/SimpleTransmission">
     <actuator name="base_motor_right" />
     <joint name="base_joint_gripper_right" />
     <mechanicalReduction>1</mechanicalReduction>
     <motorTorqueConstant>1</motorTorqueConstant>
  </transmission>
	
    <link name="gripper_right">
      <inertial>
          <mass value="0.1" />
          <origin xyz="0 0 0" />
      <inertia ixx="1.0" ixy="0.0" ixz="0.0"
               iyy="1.0" iyz="0.0" 
               izz="1.0" />
      </inertial>

      <visual>
          <origin xyz="0.0 0 0" rpy="0 0 0" />
          <geometry>
             <mesh filename="package://wsg_50_simulation/meshes/GUIDE_WSG50_110.stl" scale="0.001 0.001 0.001"/>
	     <!--box size="0.0175 0.03 0.024"/-->
          </geometry>
          <material name="black">
		<color rgba="0 0 0 0"/>
      	  </material>
      </visual>

      <collision>
          <origin xyz="0 0 0" rpy="0 0 0" />
          <geometry>
	     <!--box size="0.0175 0.03 0.024"/-->
             <mesh filename="package://wsg_50_simulation/meshes/GUIDE_WSG50_110.stl" scale="0.001 0.001 0.001"/>
         </geometry>
     </collision>
  </link>

  <gazebo reference="gripper_right">
    <material>Gazebo/White</material>
    <turnGravityOff>false</turnGravityOff>
  </gazebo>

  <!-- RIGHT FINGER -->

  <joint name="guide_joint_finger_right" type="fixed">
     <origin xyz="0 0 0.023" rpy="0 0 0" />
     <parent link="gripper_right"/>
     <child link="finger_right" />
     <dynamics friction="100" damping="100" />
     <axis xyz="1 0 0"/>
     <limit effort="100" velocity="100"/>
  </joint>

  <link name="finger_right">
      <inertial>
          <mass value="0.1" />
          <origin xyz="0 0 0" />
      <inertia ixx="1.0" ixy="0.0" ixz="0.0"
               iyy="1.0" iyz="0.0" 
               izz="1.0" />
      </inertial>

      <visual>
          <origin xyz="0.0 0 0" rpy="0 0 0" />
          <geometry>
             <mesh filename="package://wsg_50_simulation/meshes/WSG-FMF.stl" scale="0.001 0.001 0.001"/>
          </geometry>
          <material name="black">
		<color rgba="0 0 0 0"/>
      	  </material>
      </visual>

      <collision>
          <origin xyz="0 0 0" rpy="0 0 0" />
          <geometry>
             <mesh filename="package://wsg_50_simulation/meshes/WSG-FMF.stl" scale="0.001 0.001 0.001"/>
         </geometry>
     </collision>
  </link>

  <gazebo reference="finger_right">
    <material>Gazebo/White</material>
    <turnGravityOff>false</turnGravityOff>
  </gazebo>

  

  <!-- Gazebo controllers -->
  <gazebo>
     <controller:gazebo_ros_time name="gazebo_ros_time" plugin="libgazebo_ros_time.so">
       <alwaysOn>true</alwaysOn>
       <updateRate>1000.0</updateRate>
       <interface:audio name="dummy_gazebo_ros_time_iface_should_not_be_here"/>
     </controller:gazebo_ros_time>

  </gazebo>



</robot>

